<?xml version="1.0" encoding="UTF-8"?>
<sdf version="1.9">
  <world name="hoist_horizontal">
    
    <!-- ================= 核心系统插件部分 (新增) ================= -->
    <plugin filename="gz-sim-physics-system" name="gz::sim::systems::Physics"></plugin>
    <plugin filename="gz-sim-user-commands-system" name="gz::sim::systems::UserCommands"></plugin>
    <plugin filename="gz-sim-scene-broadcaster-system" name="gz::sim::systems::SceneBroadcaster"></plugin>
    <plugin filename="gz-sim-sensors-system" name="gz::sim::systems::Sensors">
      <render_engine>ogre2</render_engine>
    </plugin>
    <!-- 传感器数据生成插件：解决 QGC 报错的核心 -->
    <plugin filename="gz-sim-imu-system" name="gz::sim::systems::Imu"></plugin>
    <plugin filename="gz-sim-magnetometer-system" name="gz::sim::systems::Magnetometer"></plugin>
    <plugin filename="gz-sim-altimeter-system" name="gz::sim::systems::Altimeter"></plugin>
    <plugin filename="gz-sim-navsat-system" name="gz::sim::systems::NavSat"></plugin>
    <plugin filename="gz-sim-air-pressure-system" name="gz::sim::systems::AirPressure"></plugin>
    <!-- ========================================================= -->

    <physics type="ode">
      <max_step_size>0.004</max_step_size>
      <real_time_factor>1.0</real_time_factor>
      <real_time_update_rate>250</real_time_update_rate>
    </physics>
    <gravity>0 0 -9.8</gravity>
    <magnetic_field>6e-06 2.3e-05 -4.2e-05</magnetic_field>
    <atmosphere type="adiabatic"/>
    
    <scene>
      <grid>false</grid>
      <ambient>0.4 0.4 0.4 1</ambient>
      <background>0.7 0.7 0.7 1</background>
      <shadows>true</shadows>
    </scene>
    
    <model name="ground_plane">
      <static>true</static>
      <link name="link">
        <collision name="collision">
          <geometry>
            <plane>
              <normal>0 0 1</normal>
              <size>1 1</size>
            </plane>
          </geometry>
          <surface>
            <friction>
              <ode/>
            </friction>
            <bounce/>
            <contact/>
          </surface>
        </collision>
        <visual name="visual">
          <geometry>
            <plane>
              <normal>0 0 1</normal>
              <size>500 500</size>
            </plane>
          </geometry>
          <material>
            <ambient>0.8 0.8 0.8 1</ambient>
            <diffuse>0.8 0.8 0.8 1</diffuse>
            <specular>0.8 0.8 0.8 1</specular>
          </material>
        </visual>
        <pose>0 0 0 0 -0 0</pose>
        <inertial>
          <pose>0 0 0 0 -0 0</pose>
          <mass>1</mass>
          <inertia>
            <ixx>1</ixx>
            <ixy>0</ixy>
            <ixz>0</ixz>
            <iyy>1</iyy>
            <iyz>0</iyz>
            <izz>1</izz>
          </inertia>
        </inertial>
        <enable_wind>false</enable_wind>
      </link>
      <pose>0 0 0 0 -0 0</pose>
      <self_collide>false</self_collide>
    </model>
    
    <light name="sunUTC" type="directional">
      <pose>0 0 500 0 -0 0</pose>
      <cast_shadows>true</cast_shadows>
      <intensity>1</intensity>
      <direction>0.001 0.625 -0.78</direction>
      <diffuse>0.904 0.904 0.904 1</diffuse>
      <specular>0.271 0.271 0.271 1</specular>
      <attenuation>
        <range>2000</range>
        <linear>0</linear>
        <constant>1</constant>
        <quadratic>0</quadratic>
      </attenuation>
      <spot>
        <inner_angle>0</inner_angle>
        <outer_angle>0</outer_angle>
        <falloff>0</falloff>
      </spot>
    </light>
    
    <spherical_coordinates>
      <surface_model>EARTH_WGS84</surface_model>
      <world_frame_orientation>ENU</world_frame_orientation>
      <latitude_deg>47.397971057728974</latitude_deg>
      <longitude_deg>8.546163739800146</longitude_deg>
      <elevation>0</elevation>
    </spherical_coordinates>

    <!-- ================= 核心模型部分 ================= -->
    
    <!-- 1. 红球 (负载) -->
    <include>
      <name>payload_ball</name>
      <!-- 移动到 X=1.0 的位置 -->
      <pose>1.0 0 0.1 0 0 0</pose>
      <uri>model://red_ball</uri>
    </include>

    <!-- 2. 绳子 -->
    <include>
      <name>rope</name>
      <!-- 平移到1.0的位置，并绕Z轴旋转180度(3.14159弧度)，使其反向指回原点 -->
      <pose>1.0 0 0.1 0 0 3.14159</pose>
      <uri>model://rope</uri>
    </include>

    <!-- 3. 无人机 -->
    <include>
      <name>x500_mono_cam_down</name>
      <!-- 移动到原点 X=0 的位置 -->
      <pose>0 0 0.1 0 0 0</pose>
      <uri>model://x500_mono_cam_down</uri>
    </include>

    <!-- ================= 关节约束部分 ================= -->
    
    <!-- 无人机与绳子顶端连接 (保持不变) -->
    <joint name="uav_rope_joint" type="ball">
      <parent>rope::end_link</parent>
      <child>x500_mono_cam_down::base_link</child>
    </joint>

    <!-- 负载红球与绳子底端连接 (保持不变) -->
    <joint name="ball_rope_joint" type="ball">
      <parent>payload_ball::ball_link</parent>
      <child>rope::begin_link</child>
    </joint>

  </world>
</sdf>