<?xml version="1.0" encoding="UTF-8"?>
<sdf version="1.9">
  <world name="slung_horizontal">
    
    <!-- ================= 核心系统插件 ================= -->

    <plugin filename="gz-sim-physics-system" name="gz::sim::systems::Physics"></plugin>
    <plugin filename="gz-sim-user-commands-system" name="gz::sim::systems::UserCommands"></plugin>
    <plugin filename="gz-sim-scene-broadcaster-system" name="gz::sim::systems::SceneBroadcaster"></plugin>
    <plugin filename="gz-sim-sensors-system" name="gz::sim::systems::Sensors">
      <render_engine>ogre2</render_engine>
    </plugin>
    <plugin filename="gz-sim-contact-system" name="gz::sim::systems::Contact"></plugin>
    <plugin filename="gz-sim-wind-effects-system" name="gz::sim::systems::WindEffects">
      <force_approximation_scaling_factor>1</force_approximation_scaling_factor>
      <linear_velocity>0 0 0</linear_velocity>
    </plugin>
    <!-- =================  传感器插件  ================= -->
    <plugin filename="gz-sim-imu-system" name="gz::sim::systems::Imu"></plugin>
    <plugin filename="gz-sim-magnetometer-system" name="gz::sim::systems::Magnetometer"></plugin>
    <plugin filename="gz-sim-altimeter-system" name="gz::sim::systems::Altimeter"></plugin>
    <plugin filename="gz-sim-navsat-system" name="gz::sim::systems::NavSat"></plugin>
    <plugin filename="gz-sim-air-pressure-system" name="gz::sim::systems::AirPressure"></plugin>
    
    <!-- ================= GUI 界面配置 (新增) ================= -->
    <gui fullscreen="0">
      <!-- 基础3D场景 (保留原有画面) -->
      <plugin filename="MinimalScene" name="3D View">
        <gz-gui>
          <title>3D View</title>
          <property type="bool" key="show_title_bar">false</property>
          <property type="string" key="state">docked</property>
        </gz-gui>
        <engine>ogre2</engine>
        <scene>scene</scene>
        <ambient_light>0.4 0.4 0.4</ambient_light>
        <background_color>0.7 0.7 0.7</background_color>
        <camera_pose>-5 0 3 0 0.3 0</camera_pose>
      </plugin>

      <!-- 场景控制器 -->
      <plugin filename="GzSceneManager" name="Scene Manager">
        <gz-gui>
          <property key="resizable" type="bool">false</property>
          <property key="width" type="double">5</property>
          <property key="height" type="double">5</property>
          <property key="state" type="string">floating</property>
          <property key="show_title_bar" type="bool">false</property>
        </gz-gui>
      </plugin>
      <plugin filename="InteractiveViewControl" name="Interactive view control">
        <gz-gui>
          <property key="resizable" type="bool">false</property>
          <property key="width" type="double">5</property>
          <property key="height" type="double">5</property>
          <property key="state" type="string">floating</property>
          <property key="show_title_bar" type="bool">false</property>
        </gz-gui>
      </plugin>

      <!-- 播放/暂停控制 -->
      <plugin filename="WorldControl" name="World control">
        <gz-gui>
          <title>World control</title>
          <property type="bool" key="show_title_bar">false</property>
          <property type="bool" key="resizable">false</property>
          <property type="double" key="height">72</property>
          <property type="double" key="width">121</property>
          <property type="double" key="z">1</property>
          <property type="string" key="state">floating</property>
          <property type="anchors" key="anchors">
            <gz-gui>
              <anchors target="3D View">
                <line own="left" target="left"/>
                <line own="bottom" target="bottom"/>
              </anchors>
            </gz-gui>
          </property>
        </gz-gui>
        <play_pause>true</play_pause>
        <step>true</step>
        <start_paused>true</start_paused>
        <use_event>true</use_event>
      </plugin>

      <!-- 世界状态统计 -->
      <plugin filename="WorldStats" name="World stats">
        <gz-gui>
          <title>World stats</title>
          <property type="bool" key="show_title_bar">false</property>
          <property type="bool" key="resizable">false</property>
          <property type="double" key="height">110</property>
          <property type="double" key="width">290</property>
          <property type="double" key="z">1</property>
          <property type="string" key="state">floating</property>
          <property type="anchors" key="anchors">
            <gz-gui>
              <anchors target="3D View">
                <line own="right" target="right"/>
                <line own="bottom" target="bottom"/>
              </anchors>
            </gz-gui>
          </property>
        </gz-gui>
        <sim_time>true</sim_time>
        <real_time>true</real_time>
        <real_time_factor>true</real_time_factor>
        <iterations>true</iterations>
      </plugin>

      <!-- 实体模型树 -->
      <plugin filename="EntityTree" name="Entity tree">
        <gz-gui>
          <property type="string" key="state">docked</property>
        </gz-gui>
      </plugin>

      <!-- ================= 核心新增：机载摄像头画面显示 ================= -->
      <plugin filename="ImageDisplay" name="Image Display">
        <gz-gui>
          <title>UAV Camera Feed</title>
          <property key="state" type="string">docked</property>
        </gz-gui>
        <topic>/world/slung_horizontal/model/x500_mono_cam_down/link/camera_link/sensor/imager/image</topic>
      </plugin>
    </gui>

    <!-- ========================================================= -->

    <physics type="ode">
      <max_step_size>0.004</max_step_size>
      <real_time_factor>1.0</real_time_factor>
      <real_time_update_rate>250</real_time_update_rate>
    </physics>
    <gravity>0 0 -9.8</gravity>
    <magnetic_field>6e-06 2.3e-05 -4.2e-05</magnetic_field>
    <atmosphere type="adiabatic"/>
    
    <scene>
      <grid>false</grid>
      <ambient>0.4 0.4 0.4 1</ambient>
      <background>0.7 0.7 0.7 1</background>
      <shadows>true</shadows>
    </scene>
    
    <model name="ground_plane">
      <static>true</static>
      <link name="link">
        <collision name="collision">
          <geometry>
            <plane>
              <normal>0 0 1</normal>
              <size>1 1</size>
            </plane>
          </geometry>
          <surface>
            <friction>
              <ode/>
            </friction>
            <bounce/>
            <contact/>
          </surface>
        </collision>
        <visual name="visual">
          <geometry>
            <plane>
              <normal>0 0 1</normal>
              <size>500 500</size>
            </plane>
          </geometry>
          <material>
            <ambient>0.8 0.8 0.8 1</ambient>
            <diffuse>0.8 0.8 0.8 1</diffuse>
            <specular>0.8 0.8 0.8 1</specular>
          </material>
        </visual>
        <pose>0 0 0 0 -0 0</pose>
        <inertial>
          <pose>0 0 0 0 -0 0</pose>
          <mass>1</mass>
          <inertia>
            <ixx>1</ixx>
            <ixy>0</ixy>
            <ixz>0</ixz>
            <iyy>1</iyy>
            <iyz>0</iyz>
            <izz>1</izz>
          </inertia>
        </inertial>
        <enable_wind>false</enable_wind>
      </link>
      <pose>0 0 0 0 -0 0</pose>
      <self_collide>false</self_collide>
    </model>
    
    <light name="sunUTC" type="directional">
      <pose>0 0 500 0 -0 0</pose>
      <cast_shadows>true</cast_shadows>
      <intensity>1</intensity>
      <direction>0.001 0.625 -0.78</direction>
      <diffuse>0.904 0.904 0.904 1</diffuse>
      <specular>0.271 0.271 0.271 1</specular>
      <attenuation>
        <range>2000</range>
        <linear>0</linear>
        <constant>1</constant>
        <quadratic>0</quadratic>
      </attenuation>
      <spot>
        <inner_angle>0</inner_angle>
        <outer_angle>0</outer_angle>
        <falloff>0</falloff>
      </spot>
    </light>
    
    <spherical_coordinates>
      <surface_model>EARTH_WGS84</surface_model>
      <world_frame_orientation>ENU</world_frame_orientation>
      <latitude_deg>24.623911</latitude_deg>
      <longitude_deg>118.087898</longitude_deg>
      <elevation>0</elevation>
    </spherical_coordinates>

    <!-- ================= 模型载入模块 ================= -->
    
    <!-- 1. 红球 (负载) -->
    <include>
      <name>payload_ball</name>
      <pose>1.0 0 0.1 0 0 0</pose>
      <uri>model://payload_ball</uri>
    </include>

    <!-- 2. 绳子 -->
    <include>
      <name>rope</name>
      <pose>1.0 0 0.1 0 0 3.14159</pose>
      <uri>model://rope</uri>
    </include>

    <!-- 3. 无人机 -->
    <include>
      <name>x500_mono_cam_down</name>
      <pose>0 0 0.1 0 0 0</pose>
      <uri>model://x500_mono_cam_down</uri>
    </include>

    <!-- ================= 关节约束模块 ================= -->
    
    <joint name="uav_rope_joint" type="ball">
      <parent>rope::end_link</parent>
      <child>x500_mono_cam_down::base_link</child>
    </joint>

    <joint name="ball_rope_joint" type="ball">
      <parent>payload_ball::ball_link</parent>
      <child>rope::begin_link</child>
    </joint>

  </world>
</sdf>