<?xml version="1.0" encoding="UTF-8"?>
<sdf version="1.9">
  <world name="UAV_slung_world">
    
    <!-- ================= 核心系统插件 ================= -->
    <plugin filename="gz-sim-physics-system" name="gz::sim::systems::Physics"></plugin>
    <plugin filename="gz-sim-user-commands-system" name="gz::sim::systems::UserCommands"></plugin>
    <plugin filename="gz-sim-scene-broadcaster-system" name="gz::sim::systems::SceneBroadcaster"></plugin>
    <plugin filename="gz-sim-sensors-system" name="gz::sim::systems::Sensors">
      <render_engine>ogre2</render_engine>
    </plugin>
    <plugin filename="gz-sim-contact-system" name="gz::sim::systems::Contact"></plugin>
    <plugin filename="gz-sim-wind-effects-system" name="gz::sim::systems::WindEffects">
      <force_approximation_scaling_factor>1</force_approximation_scaling_factor>
      <linear_velocity>0 0 0</linear_velocity>
    </plugin>

    <!-- ================= 传感器插件 ================= -->
    <plugin filename="gz-sim-imu-system" name="gz::sim::systems::Imu"></plugin>
    <plugin filename="gz-sim-magnetometer-system" name="gz::sim::systems::Magnetometer"></plugin>
    <plugin filename="gz-sim-altimeter-system" name="gz::sim::systems::Altimeter"></plugin>
    <plugin filename="gz-sim-navsat-system" name="gz::sim::systems::NavSat"></plugin>
    <plugin filename="gz-sim-air-pressure-system" name="gz::sim::systems::AirPressure"></plugin>
    
    <!-- ================= 物理引擎配置 ================= -->
    <physics type="ode">
      <max_step_size>0.004</max_step_size>
      <real_time_factor>1.0</real_time_factor>
      <real_time_update_rate>250</real_time_update_rate>
    </physics>
    <gravity>0 0 -9.8</gravity>
    <magnetic_field>6e-06 2.3e-05 -4.2e-05</magnetic_field>
    <atmosphere type="adiabatic"/>
    
    <scene>
      <grid>true</grid>
      <ambient>0.4 0.4 0.4 1</ambient>
      <background>0.7 0.7 0.7 1</background>
      <shadows>true</shadows>
    </scene>
    
    <!-- ================= 基础地面与环境模型 ================= -->
    <model name="ground_plane">
      <static>true</static>
      <link name="link">
        <collision name="collision">
          <geometry>
            <plane>
              <normal>0 0 1</normal>
              <size>1 1</size>
            </plane>
          </geometry>
          <surface>
            <friction>
              <ode/>
            </friction>
          </surface>
        </collision>
        <visual name="visual">
          <geometry>
            <plane>
              <normal>0 0 1</normal>
              <size>500 500</size>
            </plane>
          </geometry>
          <material>
            <ambient>0.8 0.8 0.8 1</ambient>
            <diffuse>0.8 0.8 0.8 1</diffuse>
            <specular>0.8 0.8 0.8 1</specular>
          </material>
        </visual>
      </link>
    </model>

    <!-- 篮球场模型加载 -->
    <include>
      <name>basketball_court</name>
      <uri>model://basketball_court</uri>
      <pose>0 0 0 0 0 0</pose>
    </include>

    <light name="sunUTC" type="directional">
      <pose>0 0 500 0 -0 0</pose>
      <cast_shadows>true</cast_shadows>
      <intensity>1</intensity>
      <direction>0.001 0.625 -0.78</direction>
      <diffuse>0.904 0.904 0.904 1</diffuse>
      <specular>0.271 0.271 0.271 1</specular>
      <attenuation>
        <range>2000</range>
        <constant>1</constant>
      </attenuation>
    </light>
    
    <spherical_coordinates>
      <surface_model>EARTH_WGS84</surface_model>
      <world_frame_orientation>ENU</world_frame_orientation>
      <latitude_deg>24.623911</latitude_deg>
      <longitude_deg>118.087898</longitude_deg>
      <elevation>0</elevation>
    </spherical_coordinates>

    <!-- ================= 无人机与吊挂负载模块 ================= -->
    
    <!-- 1. 红球 (负载) -->
    <include>
      <name>payload_ball</name>
      <!-- 初始位置稍微抬高 0.1m 以防与地面模型冲突 -->
      <pose>1.0 0 1.25 0 0 0</pose>
      <uri>model://payload_ball</uri>
    </include>

    <!-- 2. 绳子 -->
    <include>
      <name>rope</name>
      <pose>1.0 0 1.25 0 0 3.14159</pose>
      <uri>model://rope</uri>
    </include>

    <!-- 3. 无人机 (x500) -->
    <include>
      <name>x500_mono_cam_down</name>
      <pose>0 0 1.25 0 0 0</pose>
      <uri>model://x500_mono_cam_down</uri>
    </include>

    <!-- ================= 关节约束 (物理连接) ================= -->
    
    <!-- 连接绳子末端与无人机机体 -->
    <joint name="uav_rope_joint" type="ball">
      <parent>rope::end_link</parent>
      <child>x500_mono_cam_down::base_link</child>
    </joint>

    <!-- 连接红球与绳子前端 -->
    <joint name="ball_rope_joint" type="ball">
      <parent>payload_ball::ball_link</parent>
      <child>rope::begin_link</child>
    </joint>

  </world>
</sdf>